Workbook
Name Slicer_Diabates_status1: #N/A
Name Slicer_HBA1C: #N/A
Name Slicer_Heart_Issues: #N/A
Name Slicer_State_ID: #N/A
Name Slicer_Weight_status: #N/A

Sheet Customer Names
A1: Customer ID | B1: name
A2: Id1 | B2: Hawks, Ms. Kelly
A3: Id2 | B3: Lehner, Mr. Matthew D
A4: Id3 | B4: Lu, Mr. Phil
A5: Id4 | B5: Osborne, Ms. Kelsey
A6: Id5 | B6: Kadala, Ms. Kristyn
A7: Id6 | B7: Baker, Mr. Russell B.
A8: Id7 | B8: Macpherson, Mr. Scott
A9: Id8 | B9: Hallman, Mr. Stephen
A10: Id9 | B10: Moran, Mr. Patrick R.
A11: Id10 | B11: Benner, Ms. Brooke N.
A12: Id11 | B12: Fierro Vargas, Ms. Paola Andrea
... A2336: Id2335 | B2336: German, Mr. Aaron K

Sheet Medical Examination
A1: Customer ID | B1: BMI | C1: HBA1C | D1: Heart Issues | E1: Any Transplants | F1: Cancer history | G1: NumberOfMajorSurgeries | H1: smoker
A2: Id1 | B2: 47.41 | C2: 7.47 | D2: No | E2: No | F2: No | G2: No major surgery | H2: yes
A3: Id2 | B3: 30.36 | C3: 5.77 | D3: No | E3: No | F3: No | G3: No major surgery | H3: yes
A4: Id3 | B4: 34.485 | C4: 11.87 | D4: yes | E4: No | F4: No | G4: 2 | H4: yes | J4: count of missing value marked with "?" | K4: =COUNTIF(A2:H2336,"?") -> 2
A5: Id4 | B5: 38.095 | C5: 6.05 | D5: No | E5: No | F5: No | G5: No major surgery | H5: yes
A6: Id5 | B6: 35.53 | C6: 5.45 | D6: No | E6: No | F6: No | G6: No major surgery | H6: yes
A7: Id6 | B7: 32.8 | C7: 6.59 | D7: No | E7: No | F7: No | G7: No major surgery | H7: yes
A8: Id7 | B8: 36.4 | C8: 6.07 | D8: No | E8: No | F8: No | G8: No major surgery | H8: yes
A9: Id8 | B9: 36.96 | C9: 7.93 | D9: No | E9: No | F9: No | G9: 3 | H9: yes
A10: Id9 | B10: 41.14 | C10: 9.58 | D10: yes | E10: No | F10: Yes | G10: 1 | H10: yes
A11: Id10 | B11: 38.06 | C11: 10.79 | D11: No | E11: No | F11: No | G11: No major surgery | H11: yes
A12: Id11 | B12: 37.7 | C12: 5.96 | D12: yes | E12: No | F12: No | G12: 2 | H12: yes
A13: Id12 | B13: 42.13 | C13: 11.9 | D13: No | E13: No | F13: No | G13: No major surgery | H13: yes
A14: Id13 | B14: 40.92 | C14: 8.41 | D14: No | E14: No | F14: No | G14: No major surgery | H14: yes
A15: Id14 | B15: 40.565 | C15: 7.02 | D15: No | E15: No | F15: No | G15: No major surgery | H15: yes
A16: Id15 | B16: 36.385 | C16: 7.59 | D16: yes | E16: No | F16: No | G16: 2 | H16: yes
A17: Id16 | B17: 39.9 | C17: 11.32 | D17: No | E17: No | F17: No | G17: No major surgery | H17: yes
A18: Id17 | B18: 33.8 | C18: 7.67 | D18: No | E18: No | F18: No | G18: 3 | H18: yes
A19: Id18 | B19: 36.765 | C19: 7.29 | D19: yes | E19: No | F19: Yes | G19: 1 | H19: yes
A20: Id19 | B20: 36.955 | C20: 4.72 | D20: yes | E20: No | F20: No | G20: 1 | H20: yes
A21: Id20 | B21: 42.9 | C21: 11.41 | D21: No | E21: No | F21: No | G21: No major surgery | H21: yes
A22: Id21 | B22: 36.3 | C22: 11.5 | D22: yes | E22: No | F22: No | G22: 2 | H22: yes
A23: Id22 | B23: 32.2 | C23: 6.22 | D23: yes | E23: No | F23: No | G23: 2 | H23: yes
A24: Id23 | B24: 31.3 | C24: 11.38 | D24: No | E24: No | F24: No | G24: 3 | H24: yes
A25: Id24 | B25: 41.8 | C25: 7.89 | D25: yes | E25: No | F25: No | G25: 2 | H25: yes
A26: Id25 | B26: 35.09 | C26: 4.38 | D26: yes | E26: No | F26: No | G26: 2 | H26: yes
A27: Id26 | B27: 33.88 | C27: 7.01 | D27: No | E27: No | F27: No | G27: 3 | H27: yes
A28: Id27 | B28: 30.875 | C28: 11.88 | D28: No | E28: No | F28: No | G28: No major surgery | H28: yes
A29: Id28 | B29: 36.86 | C29: 5.19 | D29: yes | E29: No | F29: Yes | G29: 1 | H29: yes
A30: Id29 | B30: 35.86 | C30: 6.74 | D30: yes | E30: No | F30: No | G30: 2 | H30: yes
A31: Id30 | B31: 37.05 | C31: 8.44 | D31: No | E31: No | F31: No | G31: No major surgery | H31: yes
A32: Id31 | B32: 43.89 | C32: 8.71 | D32: No | E32: No | F32: No | G32: No major surgery | H32: yes
A33: Id32 | B33: 42.35 | C33: 5.08 | D33: yes | E33: No | F33: No | G33: No major surgery | H33: yes
A34: Id33 | B34: 31.35 | C34: 6.86 | D34: No | E34: No | F34: No | G34: No major surgery | H34: yes
A35: Id34 | B35: 47.6 | C35: 5.95 | D35: yes | E35: No | F35: No | G35: No major surgery | H35: yes
A36: Id35 | B36: 46.2 | C36: 6.09 | D36: No | E36: No | F36: Yes | G36: 1 | H36: yes
A37: Id36 | B37: 32.015 | C37: 11.75 | D37: No | E37: No | F37: No | G37: No major surgery | H37: yes
A38: Id37 | B38: 40.565 | C38: 7.37 | D38: No | E38: No | F38: No | G38: No major surgery | H38: yes
A39: Id38 | B39: 32.45 | C39: 11.91 | D39: No | E39: No | F39: No | G39: No major surgery | H39: yes
A40: Id39 | B40: 34.96 | C40: 6.52 | D40: No | E40: No | F40: No | G40: No major surgery | H40: yes
...

Sheet Hospitalisation Details
A1: Customer ID | B1: year | C1: month | D1: date | E1: children | F1: charges | G1: Hospital tier | H1: City tier | I1: State ID
A2: Id2335 | B2: 1992 | C2: Jul | D2: 9 | E2: 0 | F2: 563.84 | G2: tier - 2 | H2: tier - 3 | I2: R1013
A3: Id2334 | B3: 1992 | C3: Nov | D3: 30 | E3: 0 | F3: 570.62 | G3: tier - 2 | H3: tier - 1 | I3: R1013
A4: Id2333 | B4: 1993 | C4: Jun | D4: 30 | E4: 0 | F4: 600 | G4: tier - 2 | H4: tier - 1 | I4: R1013
A5: Id2332 | B5: 1992 | C5: Sep | D5: 13 | E5: 0 | F5: 604.54 | G5: tier - 3 | H5: tier - 3 | I5: R1013
A6: Id2331 | B6: 1998 | C6: Jul | D6: 27 | E6: 0 | F6: 637.26 | G6: tier - 3 | H6: tier - 3 | I6: R1013 | K6: count of missing value marked with "?" | L6: =COUNTIF(A2:I2344,"?") -> 15
A7: Id2330 | B7: 2001 | C7: Nov | D7: 20 | E7: 0 | F7: 646.14 | G7: tier - 3 | H7: tier - 3 | I7: R1012
A8: Id2329 | B8: 1993 | C8: Jun | D8: 1 | E8: 0 | F8: 650 | G8: tier - 3 | H8: tier - 3 | I8: R1013
A9: Id2328 | B9: 1995 | C9: Jul | D9: 4 | E9: 0 | F9: 650 | G9: tier - 3 | H9: tier - 3 | I9: R1013
A10: Id2327 | B10: 2002 | C10: Nov | D10: 29 | E10: 0 | F10: 668 | G10: tier - 3 | H10: tier - 2 | I10: R1012
A11: Id2326 | B11: 1997 | C11: Nov | D11: 9 | E11: 0 | F11: 670 | G11: tier - 3 | H11: tier - 3 | I11: R1013
A12: Id2325 | B12: 2001 | C12: Sep | D12: 12 | E12: 0 | F12: 687.54 | G12: tier - 3 | H12: tier - 2 | I12: R1013
A13: Id2324 | B13: 1999 | C13: Dec | D13: 26 | E13: 0 | F13: 700 | G13: ? | H13: tier - 3 | I13: R1013
A14: Id2323 | B14: 1999 | C14: Dec | D14: 14 | E14: 0 | F14: 722.99 | G14: tier - 3 | H14: tier - 1 | I14: R1013
A15: Id2322 | B15: 2002 | C15: ? | D15: 19 | E15: 0 | F15: 750 | G15: tier - 3 | H15: tier - 1 | I15: R1012
A16: Id2321 | B16: 1993 | C16: Aug | D16: 9 | E16: 0 | F16: 760 | G16: tier - 3 | H16: tier - 1 | I16: R1013
A17: Id2320 | B17: 1996 | C17: Oct | D17: 22 | E17: 0 | F17: 760 | G17: tier - 3 | H17: tier - 3 | I17: R1013
A18: Id2319 | B18: 1993 | C18: Jun | D18: 28 | E18: 0 | F18: 770 | G18: tier - 3 | H18: tier - 3 | I18: R1013
... A1050: Id1290 | B1050: 1977 | C1050: Jul | D1050: 26 | E1050: 2 | F1050: 8527.53 | G1050: tier - 2 | H1050: tier - 2 | I1050: R1013
A1051: Id1289 | B1051: ? | C1051: Jul | D1051: 24 | E1051: 0 | F1051: 8534.67 | G1051: tier - 2 | H1051: tier - 3 | I1051: R1024
A1052: Id1288 | B1052: 1981 | C1052: Dec | D1052: 27 | E1052: 3 | F1052: 8538.29 | G1052: tier - 2 | H1052: tier - 3 | I1052: R1024
A1053: Id1287 | B1053: 1975 | C1053: Nov | D1053: 6 | E1053: 1 | F1053: 8539.67 | G1053: tier - 2 | H1053: tier - 3 | I1053: R1011
A1054: Id1286 | B1054: ? | C1054: Dec | D1054: 12 | E1054: 1 | F1054: 8547.69 | G1054: tier - 2 | H1054: tier - 1 | I1054: R1013
A1055: Id1285 | B1055: 1975 | C1055: Aug | D1055: 6 | E1055: 1 | F1055: 8551.35 | G1055: tier - 2 | H1055: tier - 2 | I1055: R1011
A1056: Id1284 | B1056: 1975 | C1056: Aug | D1056: 21 | E1056: 1 | F1056: 8556.91 | G1056: tier - 2 | H1056: tier - 1 | I1056: R1011
A1057: Id1283 | B1057: 1988 | C1057: Sep | D1057: 21 | E1057: 3 | F1057: 8567.25 | G1057: tier - 2 | H1057: tier - 1 | I1057: R1012
A1058: Id1282 | B1058: 1975 | C1058: Sep | D1058: 26 | E1058: 1 | F1058: 8569.86 | G1058: tier - 2 | H1058: tier - 3 | I1058: R1013
A1059: Id1281 | B1059: 1982 | C1059: Dec | D1059: 6 | E1059: 3 | F1059: 8572.04 | G1059: tier - 2 | H1059: tier - 2 | I1059: R1021
A1060: Id1280 | B1060: 1987 | C1060: Nov | D1060: 11 | E1060: 3 | F1060: 8573.3 | G1060: tier - 2 | H1060: tier - 2 | I1060: R1021
A1061: Id1279 | B1061: 1983 | C1061: Dec | D1061: 30 | E1061: 5 | F1061: 8582.3 | G1061: tier - 2 | H1061: tier - 1 | I1061: R1013
A1062: Id1278 | B1062: 1983 | C1062: Jul | D1062: 25 | E1062: 5 | F1062: 8596.83 | G1062: tier - 2 | H1062: tier - 3 | I1062: R1013
A1063: Id1277 | B1063: 1973 | C1063: Jul | D1063: 11 | E1063: 0 | F1063: 8601.33 | G1063: tier - 2 | H1063: tier - 1 | I1063: R1013
A1064: Id1276 | B1064: 1977 | C1064: Sep | D1064: 24 | E1064: 2 | F1064: 8603.82 | G1064: tier - 2 | H1064: tier - 1 | I1064: R1019
A1065: Id1275 | B1065: 1977 | C1065: Nov | D1065: 12 | E1065: 2 | F1065: 8604.48 | G1065: tier - 3 | H1065: tier - 2 | I1065: R1016
A1066: Id1274 | B1066: 1977 | C1066: Oct | D1066: 15 | E1066: 3 | F1066: 8605.36 | G1066: tier - 2 | H1066: tier - 2 | I1066: R1013
... A2344: Id1 | B2344: 1968 | C2344: Oct | D2344: 12 | E2344: 0 | F2344: 63770.43 | G2344: tier - 1 | H2344: tier - 3 | I2344: R1013

Sheet assign_Customer Names 
A1: Customer ID | B1: Title | C1: Name | D1: First Name | E1: Last name
A2: Id1 | B2: Hawks | C2: Ms. Kelly | D2: kelly | E2: Kelly
A3: Id2 | B3: Lehner | C3: Mr. Matthew D | D3: Matthew | E3: D
A4: Id3 | B4: Lu | C4: Mr. Phil | D4: phil | E4: Phil
A5: Id4 | B5: Osborne | C5: Ms. Kelsey | D5: kelsey | E5: Kelsey
A6: Id5 | B6: Kadala | C6: Ms. Kristyn | D6: kristyn | E6: Kristyn
A7: Id6 | B7: Baker | C7: Mr. Russell B. | D7: Russell | E7: B
A8: Id7 | B8: Macpherson | C8: Mr. Scott | D8: scott | E8: Scott
A9: Id8 | B9: Hallman | C9: Mr. Stephen | D9: stephen | E9: Stephen
A10: Id9 | B10: Moran | C10: Mr. Patrick R. | D10: Patrick | E10: R
A11: Id10 | B11: Benner | C11: Ms. Brooke N. | D11: Brooke | E11: N
A12: Id11 | B12: Fierro Vargas | C12: Ms. Paola Andrea | D12: Paola | E12: Andrea
... A1425: Id1424 | B1425: Ryder | C1425: Ms. Sharon E. | D1425: Sharon | E1425: E
A1426: Id1425 | B1426: Larsen | C1426: Mr. Jacob W√¶ver | E1426: ver
A1427: Id1426 | B1427: Keate | C1427: Mr. Scott | D1427: scott | E1427: Scott
A1428: Id1427 | B1428: Williams | C1428: Ms. Brooke S. | D1428: Brooke | E1428: S
A1429: Id1428 | B1429: Starosciak | C1429: Ms. Kaye A. | D1429: Kaye | E1429: A
A1430: Id1429 | B1430: Smith | C1430: Ms. Carolyn | D1430: carolyn | E1430: Carolyn
A1431: Id1430 | B1431: Henderson | C1431: Mr. Daniel C. | D1431: Daniel | E1431: C
A1432: Id1431 | B1432: Winkelman | C1432: Mrs. Laurie A | D1432: Laurie | E1432: A
A1433: Id1432 | B1433: Monette | C1433: Ms. Nicole | D1433: nicole | E1433: Nicole
A1434: Id1433 | B1434: Kramer | C1434: Ms. Shelby | D1434: shelby | E1434: Shelby
A1435: Id1434 | B1435: Goldstein | C1435: Ms. Allison | D1435: allison | E1435: Allison
A1436: Id1435 | B1436: Gonzalez | C1436: Ms. Leticia | D1436: leticia | E1436: Leticia
A1437: Id1436 | B1437: Barrett | C1437: Mr. John S. | D1437: John | E1437: S
A1438: Id1437 | B1438: Irwin | C1438: Ms. April | D1438: april | E1438: April
... A2336: Id2335 | B2336: German | C2336: Mr. Aaron K | D2336: Aaron | E2336: K

Sheet assign_Medical Examinations
A1: Customer ID | B1: BMI | C1: Weight status | D1: HBA1C | E1: Diabates status | F1: Heart Issues | G1: Any Transplants | H1: Cancer history | I1: NumberOfMajorSurgeries | J1: smoker
A2: Id1 | B2: 47.41 | C2: =IF(B2<18.5,"Underweight",IF(B2<25,"Normal Weight",IF(B2<30,"OverWeight","Obesity"))) -> Obesity | D2: 7.47 | E2: =IF(D2<5.7,"Normal",IF(D2<6.5,"Prediabetes","Diabetes")) -> Diabetes | F2: No | G2: No | H2: No | I2: 0 | J2: Yes
A3: Id2 | B3: 30.36 | C3: =IF(B3<18.5,"Underweight",IF(B3<25,"Normal Weight",IF(B3<30,"OverWeight","Obesity"))) -> Obesity | D3: 5.77 | E3: =IF(D3<5.7,"Normal",IF(D3<6.5,"Prediabetes","Diabetes")) -> Prediabetes | F3: No | G3: No | H3: No | I3: 0 | J3: Yes
A4: Id3 | B4: 34.485 | C4: =IF(B4<18.5,"Underweight",IF(B4<25,"Normal Weight",IF(B4<30,"OverWeight","Obesity"))) -> Obesity | D4: 11.87 | E4: =IF(D4<5.7,"Normal",IF(D4<6.5,"Prediabetes","Diabetes")) -> Diabetes | F4: Yes | G4: No | H4: No | I4: 2 | J4: Yes | M4: =COUNTIF(A2:J2336,"?") -> 0
A5: Id4 | B5: 38.095 | C5: =IF(B5<18.5,"Underweight",IF(B5<25,"Normal Weight",IF(B5<30,"OverWeight","Obesity"))) -> Obesity | D5: 6.05 | E5: =IF(D5<5.7,"Normal",IF(D5<6.5,"Prediabetes","Diabetes")) -> Prediabetes | F5: No | G5: No | H5: No | I5: 0 | J5: Yes
A6: Id5 | B6: 35.53 | C6: =IF(B6<18.5,"Underweight",IF(B6<25,"Normal Weight",IF(B6<30,"OverWeight","Obesity"))) -> Obesity | D6: 5.45 | E6: =IF(D6<5.7,"Normal",IF(D6<6.5,"Prediabetes","Diabetes")) -> Normal | F6: No | G6: No | H6: No | I6: 0 | J6: Yes
A7: Id6 | B7: 32.8 | C7: =IF(B7<18.5,"Underweight",IF(B7<25,"Normal Weight",IF(B7<30,"OverWeight","Obesity"))) -> Obesity | D7: 6.59 | E7: =IF(D7<5.7,"Normal",IF(D7<6.5,"Prediabetes","Diabetes")) -> Diabetes | F7: No | G7: No | H7: No | I7: 0 | J7: Yes
A8: Id7 | B8: 36.4 | C8: =IF(B8<18.5,"Underweight",IF(B8<25,"Normal Weight",IF(B8<30,"OverWeight","Obesity"))) -> Obesity | D8: 6.07 | E8: =IF(D8<5.7,"Normal",IF(D8<6.5,"Prediabetes","Diabetes")) -> Prediabetes | F8: No | G8: No | H8: No | I8: 0 | J8: Yes
A9: Id8 | B9: 36.96 | C9: =IF(B9<18.5,"Underweight",IF(B9<25,"Normal Weight",IF(B9<30,"OverWeight","Obesity"))) -> Obesity | D9: 7.93 | E9: =IF(D9<5.7,"Normal",IF(D9<6.5,"Prediabetes","Diabetes")) -> Diabetes | F9: No | G9: No | H9: No | I9: 3 | J9: Yes
A10: Id9 | B10: 41.14 | C10: =IF(B10<18.5,"Underweight",IF(B10<25,"Normal Weight",IF(B10<30,"OverWeight","Obesity"))) -> Obesity | D10: 9.58 | E10: =IF(D10<5.7,"Normal",IF(D10<6.5,"Prediabetes","Diabetes")) -> Diabetes | F10: Yes | G10: No | H10: Yes | I10: 1 | J10: Yes
A11: Id10 | B11: 38.06 | C11: =IF(B11<18.5,"Underweight",IF(B11<25,"Normal Weight",IF(B11<30,"OverWeight","Obesity"))) -> Obesity | D11: 10.79 | E11: =IF(D11<5.7,"Normal",IF(D11<6.5,"Prediabetes","Diabetes")) -> Diabetes | F11: No | G11: No | H11: No | I11: 0 | J11: Yes | M11: smoker
A12: Id11 | B12: 37.7 | C12: =IF(B12<18.5,"Underweight",IF(B12<25,"Normal Weight",IF(B12<30,"OverWeight","Obesity"))) -> Obesity | D12: 5.96 | E12: =IF(D12<5.7,"Normal",IF(D12<6.5,"Prediabetes","Diabetes")) -> Prediabetes | F12: Yes | G12: No | H12: No | I12: 2 | J12: Yes | M12: {=_xlfn.UNIQUE(J2:J2336)} -> Yes | N12: =COUNTIF(J2:J2336,M12) -> 488
A13: Id12 | B13: 42.13 | C13: =IF(B13<18.5,"Underweight",IF(B13<25,"Normal Weight",IF(B13<30,"OverWeight","Obesity"))) -> Obesity | D13: 11.9 | E13: =IF(D13<5.7,"Normal",IF(D13<6.5,"Prediabetes","Diabetes")) -> Diabetes | F13: No | G13: No | H13: No | I13: 0 | J13: Yes | M13: No | N13: =COUNTIF(J3:J2337,M13) -> 1847
A14: Id13 | B14: 40.92 | C14: =IF(B14<18.5,"Underweight",IF(B14<25,"Normal Weight",IF(B14<30,"OverWeight","Obesity"))) -> Obesity | D14: 8.41 | E14: =IF(D14<5.7,"Normal",IF(D14<6.5,"Prediabetes","Diabetes")) -> Diabetes | F14: No | G14: No | H14: No | I14: 0 | J14: Yes
A15: Id14 | B15: 40.565 | C15: =IF(B15<18.5,"Underweight",IF(B15<25,"Normal Weight",IF(B15<30,"OverWeight","Obesity"))) -> Obesity | D15: 7.02 | E15: =IF(D15<5.7,"Normal",IF(D15<6.5,"Prediabetes","Diabetes")) -> Diabetes | F15: No | G15: No | H15: No | I15: 0 | J15: Yes
A16: Id15 | B16: 36.385 | C16: =IF(B16<18.5,"Underweight",IF(B16<25,"Normal Weight",IF(B16<30,"OverWeight","Obesity"))) -> Obesity | D16: 7.59 | E16: =IF(D16<5.7,"Normal",IF(D16<6.5,"Prediabetes","Diabetes")) -> Diabetes | F16: Yes | G16: No | H16: No | I16: 2 | J16: Yes
A17: Id16 | B17: 39.9 | C17: =IF(B17<18.5,"Underweight",IF(B17<25,"Normal Weight",IF(B17<30,"OverWeight","Obesity"))) -> Obesity | D17: 11.32 | E17: =IF(D17<5.7,"Normal",IF(D17<6.5,"Prediabetes","Diabetes")) -> Diabetes | F17: No | G17: No | H17: No | I17: 0 | J17: Yes
A18: Id17 | B18: 33.8 | C18: =IF(B18<18.5,"Underweight",IF(B18<25,"Normal Weight",IF(B18<30,"OverWeight","Obesity"))) -> Obesity | D18: 7.67 | E18: =IF(D18<5.7,"Normal",IF(D18<6.5,"Prediabetes","Diabetes")) -> Diabetes | F18: No | G18: No | H18: No | I18: 3 | J18: Yes
A19: Id18 | B19: 36.765 | C19: =IF(B19<18.5,"Underweight",IF(B19<25,"Normal Weight",IF(B19<30,"OverWeight","Obesity"))) -> Obesity | D19: 7.29 | E19: =IF(D19<5.7,"Normal",IF(D19<6.5,"Prediabetes","Diabetes")) -> Diabetes | F19: Yes | G19: No | H19: Yes | I19: 1 | J19: Yes
A20: Id19 | B20: 36.955 | C20: =IF(B20<18.5,"Underweight",IF(B20<25,"Normal Weight",IF(B20<30,"OverWeight","Obesity"))) -> Obesity | D20: 4.72 | E20: =IF(D20<5.7,"Normal",IF(D20<6.5,"Prediabetes","Diabetes")) -> Normal | F20: Yes | G20: No | H20: No | I20: 1 | J20: Yes
A21: Id20 | B21: 42.9 | C21: =IF(B21<18.5,"Underweight",IF(B21<25,"Normal Weight",IF(B21<30,"OverWeight","Obesity"))) -> Obesity | D21: 11.41 | E21: =IF(D21<5.7,"Normal",IF(D21<6.5,"Prediabetes","Diabetes")) -> Diabetes | F21: No | G21: No | H21: No | I21: 0 | J21: Yes
A22: Id21 | B22: 36.3 | C22: =IF(B22<18.5,"Underweight",IF(B22<25,"Normal Weight",IF(B22<30,"OverWeight","Obesity"))) -> Obesity | D22: 11.5 | E22: =IF(D22<5.7,"Normal",IF(D22<6.5,"Prediabetes","Diabetes")) -> Diabetes | F22: Yes | G22: No | H22: No | I22: 2 | J22: Yes
A23: Id22 | B23: 32.2 | C23: =IF(B23<18.5,"Underweight",IF(B23<25,"Normal Weight",IF(B23<30,"OverWeight","Obesity"))) -> Obesity | D23: 6.22 | E23: =IF(D23<5.7,"Normal",IF(D23<6.5,"Prediabetes","Diabetes")) -> Prediabetes | F23: Yes | G23: No | H23: No | I23: 2 | J23: Yes
A24: Id23 | B24: 31.3 | C24: =IF(B24<18.5,"Underweight",IF(B24<25,"Normal Weight",IF(B24<30,"OverWeight","Obesity"))) -> Obesity | D24: 11.38 | E24: =IF(D24<5.7,"Normal",IF(D24<6.5,"Prediabetes","Diabetes")) -> Diabetes | F24: No | G24: No | H24: No | I24: 3 | J24: Yes
A25: Id24 | B25: 41.8 | C25: =IF(B25<18.5,"Underweight",IF(B25<25,"Normal Weight",IF(B25<30,"OverWeight","Obesity"))) -> Obesity | D25: 7.89 | E25: =IF(D25<5.7,"Normal",IF(D25<6.5,"Prediabetes","Diabetes")) -> Diabetes | F25: Yes | G25: No | H25: No | I25: 2 | J25: Yes
... A2336: Id2335 | B2336: 17.58 | C2336: =IF(B2336<18.5,"Underweight",IF(B2336<25,"Normal Weight",IF(B2336<30,"OverWeight","Obesity"))) -> Underweight | D2336: 4.51 | E2336: =IF(D2336<5.7,"Normal",IF(D2336<6.5,"Prediabetes","Diabetes")) -> Normal | F2336: No | G2336: No | H2336: No | I2336: 1 | J2336: No

Sheet assign_Hospitalisation Details
A1: Customer ID | B1: year | C1: month | D1: date | E1: children | F1: charges | G1: Hospital tier | H1: City tier | I1: State ID | J1: Date Of Birth | K1: Age
A2: Id1 | B2: 1968 | C2: Oct | D2: 12 | E2: 0 | F2: 63770.43 | G2: tier - 1 | H2: tier - 3 | I2: R1013 | J2: =D2&"-"&C2&"-"&B2 -> 12-Oct-1968 | K2: =2025-B2 -> 57
A3: Id2 | B3: 1977 | C3: Jun | D3: 8 | E3: 0 | F3: 62592.87 | G3: tier - 2 | H3: tier - 3 | I3: R1013 | J3: =D3&"-"&C3&"-"&B3 -> 8-Jun-1977 | K3: =2025-B3 -> 48
A4: Id3 | B4: 1970 | C4: Sep | D4: 11 | E4: 3 | F4: 60021.4 | G4: tier - 1 | H4: tier - 1 | I4: R1012 | J4: =D4&"-"&C4&"-"&B4 -> 11-Sep-1970 | K4: =2025-B4 -> 55
A5: Id4 | B5: 1991 | C5: Jun | D5: 6 | E5: 1 | F5: 58571.07 | G5: tier - 1 | H5: tier - 3 | I5: R1024 | J5: =D5&"-"&C5&"-"&B5 -> 6-Jun-1991 | K5: =2025-B5 -> 34
A6: Id5 | B6: 1989 | C6: Jun | D6: 19 | E6: 0 | F6: 55135.4 | G6: tier - 1 | H6: tier - 2 | I6: R1012 | J6: =D6&"-"&C6&"-"&B6 -> 19-Jun-1989 | K6: =2025-B6 -> 36
A7: Id6 | B7: 1962 | C7: Aug | D7: 4 | E7: 0 | F7: 52590.83 | G7: tier - 1 | H7: tier - 3 | I7: R1011 | J7: =D7&"-"&C7&"-"&B7 -> 4-Aug-1962 | K7: =2025-B7 -> 63 | N7: hospital tier | Q7: city tier
A8: Id7 | B8: 1994 | C8: Oct | D8: 27 | E8: 1 | F8: 51194.56 | G8: tier - 1 | H8: tier - 3 | I8: R1011 | J8: =D8&"-"&C8&"-"&B8 -> 27-Oct-1994 | K8: =2025-B8 -> 31 | N8: {=_xlfn.UNIQUE(G2:G2344)} -> tier - 1 | O8: =COUNTIF(G2:G2344,N8) -> 309 | Q8: {=_xlfn.UNIQUE(H2:H2344)} -> tier - 3 | R8: =COUNTIF(H2:H2344,Q8) -> 796
A9: Id8 | B9: 1958 | C9: Jun | D9: 27 | E9: 2 | F9: 49577.66 | G9: tier - 2 | H9: tier - 2 | I9: R1013 | J9: =D9&"-"&C9&"-"&B9 -> 27-Jun-1958 | K9: =2025-B9 -> 67 | N9: tier - 2 | O9: =COUNTIF(G3:G2345,N9) -> 1340 | Q9: tier - 1 | R9: =COUNTIF(H3:H2345,Q9) -> 734
A10: Id9 | B10: 1963 | C10: Sep | D10: 4 | E10: 1 | F10: 48970.25 | G10: tier - 1 | H10: tier - 2 | I10: R1013 | J10: =D10&"-"&C10&"-"&B10 -> 4-Sep-1963 | K10: =2025-B10 -> 62 | N10: tier - 3 | O10: =COUNTIF(G4:G2346,N10) -> 694 | Q10: tier - 2 | R10: =COUNTIF(H4:H2346,Q10) -> 813
A11: Id10 | B11: 1978 | C11: Dec | D11: 29 | E11: 0 | F11: 48885.14 | G11: tier - 1 | H11: tier - 2 | I11: R1013 | J11: =D11&"-"&C11&"-"&B11 -> 29-Dec-1978 | K11: =2025-B11 -> 47
A12: Id11 | B12: 1959 | C12: Jul | D12: 22 | E12: 0 | F12: 48824.45 | G12: tier - 2 | H12: tier - 1 | I12: R1011 | J12: =D12&"-"&C12&"-"&B12 -> 22-Jul-1959 | K12: =2025-B12 -> 66
A13: Id12 | B13: 1965 | C13: Oct | D13: 27 | E13: 1 | F13: 48675.52 | G13: tier - 1 | H13: tier - 2 | I13: R1013 | J13: =D13&"-"&C13&"-"&B13 -> 27-Oct-1965 | K13: =2025-B13 -> 60 | M13: avg of year | N13: =ROUND(AVERAGEIF(B2:B2344,"<>?",B2:B2344),0) -> 1983
A14: Id13 | B14: 1962 | C14: Oct | D14: 11 | E14: 0 | F14: 48673.56 | G14: tier - 1 | H14: tier - 2 | I14: R1013 | J14: =D14&"-"&C14&"-"&B14 -> 11-Oct-1962 | K14: =2025-B14 -> 63
A15: Id14 | B15: 1968 | C15: Dec | D15: 1 | E15: 3 | F15: 48549.18 | G15: tier - 1 | H15: tier - 3 | I15: R1016 | J15: =D15&"-"&C15&"-"&B15 -> 1-Dec-1968 | K15: =2025-B15 -> 57
A16: Id15 | B16: 1961 | C16: Dec | D16: 21 | E16: 1 | F16: 48517.56 | G16: tier - 1 | H16: tier - 3 | I16: R1024 | J16: =D16&"-"&C16&"-"&B16 -> 21-Dec-1961 | K16: =2025-B16 -> 64
A17: Id16 | B17: 1962 | C17: Aug | D17: 27 | E17: 0 | F17: 48173.36 | G17: tier - 1 | H17: tier - 3 | I17: R1011 | J17: =D17&"-"&C17&"-"&B17 -> 27-Aug-1962 | K17: =2025-B17 -> 63
A18: Id17 | B18: 1958 | C18: Nov | D18: 16 | E18: 1 | F18: 47928.03 | G18: tier - 2 | H18: tier - 3 | I18: R1011 | J18: =D18&"-"&C18&"-"&B18 -> 16-Nov-1958 | K18: =2025-B18 -> 67
A19: Id18 | B19: 1963 | C19: Aug | D19: 5 | E19: 1 | F19: 47896.79 | G19: tier - 1 | H19: tier - 3 | I19: R1024 | J19: =D19&"-"&C19&"-"&B19 -> 5-Aug-1963 | K19: =2025-B19 -> 62
A20: Id19 | B20: 1964 | C20: Nov | D20: 7 | E20: 2 | F20: 47496.49 | G20: tier - 1 | H20: tier - 3 | I20: R1012 | J20: =D20&"-"&C20&"-"&B20 -> 7-Nov-1964 | K20: =2025-B20 -> 61
A21: Id20 | B21: 1971 | C21: Sep | D21: 27 | E21: 2 | F21: 47462.89 | G21: tier - 1 | H21: tier - 2 | I21: R1013 | J21: =D21&"-"&C21&"-"&B21 -> 27-Sep-1971 | K21: =2025-B21 -> 54
A22: Id21 | B22: 1961 | C22: Jun | D22: 13 | E22: 1 | F22: 47403.88 | G22: tier - 1 | H22: tier - 3 | I22: R1011 | J22: =D22&"-"&C22&"-"&B22 -> 13-Jun-1961 | K22: =2025-B22 -> 64
A23: Id22 | B23: 1959 | C23: Oct | D23: 4 | E23: 2 | F23: 47305.31 | G23: tier - 2 | H23: tier - 1 | I23: R1011 | J23: =D23&"-"&C23&"-"&B23 -> 4-Oct-1959 | K23: =2025-B23 -> 66
A24: Id23 | B24: 1958 | C24: Sep | D24: 3 | E24: 2 | F24: 47291.06 | G24: tier - 2 | H24: tier - 1 | I24: R1011 | J24: =D24&"-"&C24&"-"&B24 -> 3-Sep-1958 | K24: =2025-B24 -> 67
A25: Id24 | B25: 1970 | C25: Dec | D25: 28 | E25: 2 | F25: 47269.85 | G25: tier - 1 | H25: tier - 2 | I25: R1013 | J25: =D25&"-"&C25&"-"&B25 -> 28-Dec-1970 | K25: =2025-B25 -> 55
... A2344: Id999 | B2344: 1969 | C2344: Aug | D2344: 20 | E2344: 3 | F2344: 11253.42 | G2344: tier - 3 | H2344: tier - 1 | I2344: R1011 | J2344: =D2344&"-"&C2344&"-"&B2344 -> 20-Aug-1969 | K2344: =2025-B2344 -> 56

Sheet Health care
A1: Customer ID | B1: First Name | C1: BMI | D1: HBA1C | E1: Heart Issues | F1: Any Transplant | G1: Cancer History | H1: NumberOfMajorSurgeries | I1: smoker | J1: Weight status | K1: Diabates status | L1: Date Of Birth | M1: charges | N1: Hospital tier | O1: City tier | P1: State ID | Q1: Age
A2: Id1 | B2: =VLOOKUP(A2,cstm_name[#All],4,FALSE) -> kelly | C2: =VLOOKUP(A2,medical[#All],2,FALSE) -> 47.41 | D2: =VLOOKUP(A2,medical[#All],5,FALSE) -> Diabetes | E2: =VLOOKUP(A2,medical[#All],6,FALSE) -> No | F2: =VLOOKUP('Health care'!A2,medical[#All],7,FALSE) -> No | G2: =VLOOKUP(A2,medical[#All],8,FALSE) -> No | H2: =VLOOKUP('Health care'!A2,medical[#All],9,FALSE) -> 0 | I2: =VLOOKUP(A2,medical[#All],10,FALSE) -> Yes | J2: =VLOOKUP(A2,medical[#All],3,FALSE) -> Obesity | K2: =VLOOKUP(A2,medical[#All],5,FALSE) -> Diabetes | L2: =VLOOKUP(A2,hospital[#All],10,FALSE) -> 12-Oct-1968 | M2: =VLOOKUP(A2,hospital[#All],6,FALSE) -> 63770.43 | N2: =VLOOKUP(A2,hospital[#All],7,FALSE) -> tier - 1 | O2: =VLOOKUP(A2,hospital[#All],8,FALSE) -> tier - 3 | P2: =VLOOKUP(A2,hospital[#All],9,FALSE) -> R1013 | Q2: =VLOOKUP(A2,hospital[#All],11,FALSE) -> 57
A3: Id2 | B3: =VLOOKUP(A3,cstm_name[#All],4,FALSE) -> Matthew | C3: =VLOOKUP(A3,medical[#All],2,FALSE) -> 30.36 | D3: =VLOOKUP(A3,medical[#All],5,FALSE) -> Prediabetes | E3: =VLOOKUP(A3,medical[#All],6,FALSE) -> No | F3: =VLOOKUP('Health care'!A3,medical[#All],7,FALSE) -> No | G3: =VLOOKUP(A3,medical[#All],8,FALSE) -> No | H3: =VLOOKUP('Health care'!A3,medical[#All],9,FALSE) -> 0 | I3: =VLOOKUP(A3,medical[#All],10,FALSE) -> Yes | J3: =VLOOKUP(A3,medical[#All],3,FALSE) -> Obesity | K3: =VLOOKUP(A3,medical[#All],5,FALSE) -> Prediabetes | L3: =VLOOKUP(A3,hospital[#All],10,FALSE) -> 8-Jun-1977 | M3: =VLOOKUP(A3,hospital[#All],6,FALSE) -> 62592.87 | N3: =VLOOKUP(A3,hospital[#All],7,FALSE) -> tier - 2 | O3: =VLOOKUP(A3,hospital[#All],8,FALSE) -> tier - 3 | P3: =VLOOKUP(A3,hospital[#All],9,FALSE) -> R1013 | Q3: =VLOOKUP(A3,hospital[#All],11,FALSE) -> 48
A4: Id3 | B4: =VLOOKUP(A4,cstm_name[#All],4,FALSE) -> phil | C4: =VLOOKUP(A4,medical[#All],2,FALSE) -> 34.485 | D4: =VLOOKUP(A4,medical[#All],5,FALSE) -> Diabetes | E4: =VLOOKUP(A4,medical[#All],6,FALSE) -> Yes | F4: =VLOOKUP('Health care'!A4,medical[#All],7,FALSE) -> No | G4: =VLOOKUP(A4,medical[#All],8,FALSE) -> No | H4: =VLOOKUP('Health care'!A4,medical[#All],9,FALSE) -> 2 | I4: =VLOOKUP(A4,medical[#All],10,FALSE) -> Yes | J4: =VLOOKUP(A4,medical[#All],3,FALSE) -> Obesity | K4: =VLOOKUP(A4,medical[#All],5,FALSE) -> Diabetes | L4: =VLOOKUP(A4,hospital[#All],10,FALSE) -> 11-Sep-1970 | M4: =VLOOKUP(A4,hospital[#All],6,FALSE) -> 60021.4 | N4: =VLOOKUP(A4,hospital[#All],7,FALSE) -> tier - 1 | O4: =VLOOKUP(A4,hospital[#All],8,FALSE) -> tier - 1 | P4: =VLOOKUP(A4,hospital[#All],9,FALSE) -> R1012 | Q4: =VLOOKUP(A4,hospital[#All],11,FALSE) -> 55
A5: Id4 | B5: =VLOOKUP(A5,cstm_name[#All],4,FALSE) -> kelsey | C5: =VLOOKUP(A5,medical[#All],2,FALSE) -> 38.095 | D5: =VLOOKUP(A5,medical[#All],5,FALSE) -> Prediabetes | E5: =VLOOKUP(A5,medical[#All],6,FALSE) -> No | F5: =VLOOKUP('Health care'!A5,medical[#All],7,FALSE) -> No | G5: =VLOOKUP(A5,medical[#All],8,FALSE) -> No | H5: =VLOOKUP('Health care'!A5,medical[#All],9,FALSE) -> 0 | I5: =VLOOKUP(A5,medical[#All],10,FALSE) -> Yes | J5: =VLOOKUP(A5,medical[#All],3,FALSE) -> Obesity | K5: =VLOOKUP(A5,medical[#All],5,FALSE) -> Prediabetes | L5: =VLOOKUP(A5,hospital[#All],10,FALSE) -> 6-Jun-1991 | M5: =VLOOKUP(A5,hospital[#All],6,FALSE) -> 58571.07 | N5: =VLOOKUP(A5,hospital[#All],7,FALSE) -> tier - 1 | O5: =VLOOKUP(A5,hospital[#All],8,FALSE) -> tier - 3 | P5: =VLOOKUP(A5,hospital[#All],9,FALSE) -> R1024 | Q5: =VLOOKUP(A5,hospital[#All],11,FALSE) -> 34
A6: Id5 | B6: =VLOOKUP(A6,cstm_name[#All],4,FALSE) -> kristyn | C6: =VLOOKUP(A6,medical[#All],2,FALSE) -> 35.53 | D6: =VLOOKUP(A6,medical[#All],5,FALSE) -> Normal | E6: =VLOOKUP(A6,medical[#All],6,FALSE) -> No | F6: =VLOOKUP('Health care'!A6,medical[#All],7,FALSE) -> No | G6: =VLOOKUP(A6,medical[#All],8,FALSE) -> No | H6: =VLOOKUP('Health care'!A6,medical[#All],9,FALSE) -> 0 | I6: =VLOOKUP(A6,medical[#All],10,FALSE) -> Yes | J6: =VLOOKUP(A6,medical[#All],3,FALSE) -> Obesity | K6: =VLOOKUP(A6,medical[#All],5,FALSE) -> Normal | L6: =VLOOKUP(A6,hospital[#All],10,FALSE) -> 19-Jun-1989 | M6: =VLOOKUP(A6,hospital[#All],6,FALSE) -> 55135.4 | N6: =VLOOKUP(A6,hospital[#All],7,FALSE) -> tier - 1 | O6: =VLOOKUP(A6,hospital[#All],8,FALSE) -> tier - 2 | P6: =VLOOKUP(A6,hospital[#All],9,FALSE) -> R1012 | Q6: =VLOOKUP(A6,hospital[#All],11,FALSE) -> 36
A7: Id6 | B7: =VLOOKUP(A7,cstm_name[#All],4,FALSE) -> Russell | C7: =VLOOKUP(A7,medical[#All],2,FALSE) -> 32.8 | D7: =VLOOKUP(A7,medical[#All],5,FALSE) -> Diabetes | E7: =VLOOKUP(A7,medical[#All],6,FALSE) -> No | F7: =VLOOKUP('Health care'!A7,medical[#All],7,FALSE) -> No | G7: =VLOOKUP(A7,medical[#All],8,FALSE) -> No | H7: =VLOOKUP('Health care'!A7,medical[#All],9,FALSE) -> 0 | I7: =VLOOKUP(A7,medical[#All],10,FALSE) -> Yes | J7: =VLOOKUP(A7,medical[#All],3,FALSE) -> Obesity | K7: =VLOOKUP(A7,medical[#All],5,FALSE) -> Diabetes | L7: =VLOOKUP(A7,hospital[#All],10,FALSE) -> 4-Aug-1962 | M7: =VLOOKUP(A7,hospital[#All],6,FALSE) -> 52590.83 | N7: =VLOOKUP(A7,hospital[#All],7,FALSE) -> tier - 1 | O7: =VLOOKUP(A7,hospital[#All],8,FALSE) -> tier - 3 | P7: =VLOOKUP(A7,hospital[#All],9,FALSE) -> R1011 | Q7: =VLOOKUP(A7,hospital[#All],11,FALSE) -> 63
A8: Id7 | B8: =VLOOKUP(A8,cstm_name[#All],4,FALSE) -> scott | C8: =VLOOKUP(A8,medical[#All],2,FALSE) -> 36.4 | D8: =VLOOKUP(A8,medical[#All],5,FALSE) -> Prediabetes | E8: =VLOOKUP(A8,medical[#All],6,FALSE) -> No | F8: =VLOOKUP('Health care'!A8,medical[#All],7,FALSE) -> No | G8: =VLOOKUP(A8,medical[#All],8,FALSE) -> No | H8: =VLOOKUP('Health care'!A8,medical[#All],9,FALSE) -> 0 | I8: =VLOOKUP(A8,medical[#All],10,FALSE) -> Yes | J8: =VLOOKUP(A8,medical[#All],3,FALSE) -> Obesity | K8: =VLOOKUP(A8,medical[#All],5,FALSE) -> Prediabetes | L8: =VLOOKUP(A8,hospital[#All],10,FALSE) -> 27-Oct-1994 | M8: =VLOOKUP(A8,hospital[#All],6,FALSE) -> 51194.56 | N8: =VLOOKUP(A8,hospital[#All],7,FALSE) -> tier - 1 | O8: =VLOOKUP(A8,hospital[#All],8,FALSE) -> tier - 3 | P8: =VLOOKUP(A8,hospital[#All],9,FALSE) -> R1011 | Q8: =VLOOKUP(A8,hospital[#All],11,FALSE) -> 31
A9: Id8 | B9: =VLOOKUP(A9,cstm_name[#All],4,FALSE) -> stephen | C9: =VLOOKUP(A9,medical[#All],2,FALSE) -> 36.96 | D9: =VLOOKUP(A9,medical[#All],5,FALSE) -> Diabetes | E9: =VLOOKUP(A9,medical[#All],6,FALSE) -> No | F9: =VLOOKUP('Health care'!A9,medical[#All],7,FALSE) -> No | G9: =VLOOKUP(A9,medical[#All],8,FALSE) -> No | H9: =VLOOKUP('Health care'!A9,medical[#All],9,FALSE) -> 3 | I9: =VLOOKUP(A9,medical[#All],10,FALSE) -> Yes | J9: =VLOOKUP(A9,medical[#All],3,FALSE) -> Obesity | K9: =VLOOKUP(A9,medical[#All],5,FALSE) -> Diabetes | L9: =VLOOKUP(A9,hospital[#All],10,FALSE) -> 27-Jun-1958 | M9: =VLOOKUP(A9,hospital[#All],6,FALSE) -> 49577.66 | N9: =VLOOKUP(A9,hospital[#All],7,FALSE) -> tier - 2 | O9: =VLOOKUP(A9,hospital[#All],8,FALSE) -> tier - 2 | P9: =VLOOKUP(A9,hospital[#All],9,FALSE) -> R1013 | Q9: =VLOOKUP(A9,hospital[#All],11,FALSE) -> 67
A10: Id9 | B10: =VLOOKUP(A10,cstm_name[#All],4,FALSE) -> Patrick | C10: =VLOOKUP(A10,medical[#All],2,FALSE) -> 41.14 | D10: =VLOOKUP(A10,medical[#All],5,FALSE) -> Diabetes | E10: =VLOOKUP(A10,medical[#All],6,FALSE) -> Yes | F10: =VLOOKUP('Health care'!A10,medical[#All],7,FALSE) -> No | G10: =VLOOKUP(A10,medical[#All],8,FALSE) -> Yes | H10: =VLOOKUP('Health care'!A10,medical[#All],9,FALSE) -> 1 | I10: =VLOOKUP(A10,medical[#All],10,FALSE) -> Yes | J10: =VLOOKUP(A10,medical[#All],3,FALSE) -> Obesity | K10: =VLOOKUP(A10,medical[#All],5,FALSE) -> Diabetes | L10: =VLOOKUP(A10,hospital[#All],10,FALSE) -> 4-Sep-1963 | M10: =VLOOKUP(A10,hospital[#All],6,FALSE) -> 48970.25 | N10: =VLOOKUP(A10,hospital[#All],7,FALSE) -> tier - 1 | O10: =VLOOKUP(A10,hospital[#All],8,FALSE) -> tier - 2 | P10: =VLOOKUP(A10,hospital[#All],9,FALSE) -> R1013 | Q10: =VLOOKUP(A10,hospital[#All],11,FALSE) -> 62
A11: Id10 | B11: =VLOOKUP(A11,cstm_name[#All],4,FALSE) -> Brooke | C11: =VLOOKUP(A11,medical[#All],2,FALSE) -> 38.06 | D11: =VLOOKUP(A11,medical[#All],5,FALSE) -> Diabetes | E11: =VLOOKUP(A11,medical[#All],6,FALSE) -> No | F11: =VLOOKUP('Health care'!A11,medical[#All],7,FALSE) -> No | G11: =VLOOKUP(A11,medical[#All],8,FALSE) -> No | H11: =VLOOKUP('Health care'!A11,medical[#All],9,FALSE) -> 0 | I11: =VLOOKUP(A11,medical[#All],10,FALSE) -> Yes | J11: =VLOOKUP(A11,medical[#All],3,FALSE) -> Obesity | K11: =VLOOKUP(A11,medical[#All],5,FALSE) -> Diabetes | L11: =VLOOKUP(A11,hospital[#All],10,FALSE) -> 29-Dec-1978 | M11: =VLOOKUP(A11,hospital[#All],6,FALSE) -> 48885.14 | N11: =VLOOKUP(A11,hospital[#All],7,FALSE) -> tier - 1 | O11: =VLOOKUP(A11,hospital[#All],8,FALSE) -> tier - 2 | P11: =VLOOKUP(A11,hospital[#All],9,FALSE) -> R1013 | Q11: =VLOOKUP(A11,hospital[#All],11,FALSE) -> 47
A12: Id11 | B12: =VLOOKUP(A12,cstm_name[#All],4,FALSE) -> Paola | C12: =VLOOKUP(A12,medical[#All],2,FALSE) -> 37.7 | D12: =VLOOKUP(A12,medical[#All],5,FALSE) -> Prediabetes | E12: =VLOOKUP(A12,medical[#All],6,FALSE) -> Yes | F12: =VLOOKUP('Health care'!A12,medical[#All],7,FALSE) -> No | G12: =VLOOKUP(A12,medical[#All],8,FALSE) -> No | H12: =VLOOKUP('Health care'!A12,medical[#All],9,FALSE) -> 2 | I12: =VLOOKUP(A12,medical[#All],10,FALSE) -> Yes | J12: =VLOOKUP(A12,medical[#All],3,FALSE) -> Obesity | K12: =VLOOKUP(A12,medical[#All],5,FALSE) -> Prediabetes | L12: =VLOOKUP(A12,hospital[#All],10,FALSE) -> 22-Jul-1959 | M12: =VLOOKUP(A12,hospital[#All],6,FALSE) -> 48824.45 | N12: =VLOOKUP(A12,hospital[#All],7,FALSE) -> tier - 2 | O12: =VLOOKUP(A12,hospital[#All],8,FALSE) -> tier - 1 | P12: =VLOOKUP(A12,hospital[#All],9,FALSE) -> R1011 | Q12: =VLOOKUP(A12,hospital[#All],11,FALSE) -> 66
A13: Id12 | B13: =VLOOKUP(A13,cstm_name[#All],4,FALSE) -> david | C13: =VLOOKUP(A13,medical[#All],2,FALSE) -> 42.13 | D13: =VLOOKUP(A13,medical[#All],5,FALSE) -> Diabetes | E13: =VLOOKUP(A13,medical[#All],6,FALSE) -> No | F13: =VLOOKUP('Health care'!A13,medical[#All],7,FALSE) -> No | G13: =VLOOKUP(A13,medical[#All],8,FALSE) -> No | H13: =VLOOKUP('Health care'!A13,medical[#All],9,FALSE) -> 0 | I13: =VLOOKUP(A13,medical[#All],10,FALSE) -> Yes | J13: =VLOOKUP(A13,medical[#All],3,FALSE) -> Obesity | K13: =VLOOKUP(A13,medical[#All],5,FALSE) -> Diabetes | L13: =VLOOKUP(A13,hospital[#All],10,FALSE) -> 27-Oct-1965 | M13: =VLOOKUP(A13,hospital[#All],6,FALSE) -> 48675.52 | N13: =VLOOKUP(A13,hospital[#All],7,FALSE) -> tier - 1 | O13: =VLOOKUP(A13,hospital[#All],8,FALSE) -> tier - 2 | P13: =VLOOKUP(A13,hospital[#All],9,FALSE) -> R1013 | Q13: =VLOOKUP(A13,hospital[#All],11,FALSE) -> 60
... A2336: Id2335 | B2336: =VLOOKUP(A2336,cstm_name[#All],4,FALSE) -> Aaron | C2336: =VLOOKUP(A2336,medical[#All],2,FALSE) -> 17.58 | D2336: =VLOOKUP(A2336,medical[#All],5,FALSE) -> Normal | E2336: =VLOOKUP(A2336,medical[#All],6,FALSE) -> No | F2336: =VLOOKUP('Health care'!A2336,medical[#All],7,FALSE) -> No | G2336: =VLOOKUP(A2336,medical[#All],8,FALSE) -> No | H2336: =VLOOKUP('Health care'!A2336,medical[#All],9,FALSE) -> 1 | I2336: =VLOOKUP(A2336,medical[#All],10,FALSE) -> No | J2336: =VLOOKUP(A2336,medical[#All],3,FALSE) -> Underweight | K2336: =VLOOKUP(A2336,medical[#All],5,FALSE) -> Normal | L2336: =VLOOKUP(A2336,hospital[#All],10,FALSE) -> 9-Jul-1992 | M2336: =VLOOKUP(A2336,hospital[#All],6,FALSE) -> 563.84 | N2336: =VLOOKUP(A2336,hospital[#All],7,FALSE) -> tier - 2 | O2336: =VLOOKUP(A2336,hospital[#All],8,FALSE) -> tier - 3 | P2336: =VLOOKUP(A2336,hospital[#All],9,FALSE) -> R1013 | Q2336: =VLOOKUP(A2336,hospital[#All],11,FALSE) -> 33

Sheet pie or donut
A2: Distribution of cancer history among smokers and non-smokers | H2: The total number of major surgeries and average HbA1C differ between patients with and without a history of transplants
A5: Row Labels | B5: Count of Cancer History | H5: Sum of NumberOfMajorSurgeries | I5: Column Labels
A6: No | B6: 749 | H6: Row Labels | I6: Prediabetes | J6: Grand Total
A7: Yes | B7: 202 | H7: No | I7: 36 | J7: 36
A8: Grand Total | B8: 951 | H8: yes | I8: 15 | J8: 15
H9: Grand Total | I9: 51 | J9: 51

Sheet line chart
B2: Correlation between age and both BMI and HbA1C in the dataset | M2: The relationship between age and healthcare charges.
A4: Row Labels | B4: Average of BMI | L4: Row Labels | M4: Average of charges
A5: 20-24 | B5: 31.897115 | L5: 20-24 | M5: 8058.6775
A6: 25-29 | B6: 30.393611 | L6: 25-29 | M6: 10117.673
A7: 30-34 | B7: 31.771831 | L7: 30-34 | M7: 11200.104
A8: 35-39 | B8: 31.538676 | L8: 35-39 | M8: 12206.207
A9: 40-44 | B9: 31.423182 | L9: 40-44 | M9: 11547.14
A10: 45-49 | B10: 29.337692 | L10: 45-49 | M10: 15855.022
A11: 50-54 | B11: 28.8705 | L11: 50-54 | M11: 16515.404
A12: Grand Total | B12: 30.924094 | L12: Grand Total | M12: 11655.635

Sheet bar or column
B2: Healthcare charges vary based on different weight statuses and diabetes statuses | J2: The average charges for each hospital tier within different states
A4: Row Labels | B4: Sum of charges
A5: Normal Weight | B5: 1577298.8 | J5: Row Labels | K5: Average of charges
A6: Obase | B6: 7086520.5 | J6: tier - 1 | K6: 26570.102
A7: OverWeight | B7: 2131399.9 | J7: tier - 2 | K7: 6392.2776
A8: Underweight | B8: 289289.42 | J8: tier - 3 | K8: 3154.6974
A9: Grand Total | B9: 11084509 | J9: Grand Total | K9: 8258.8076

Sheet Dashboard
B1: Healthcare Performance Dashboard
